2021-06-27 18:40:30,882 - instabot version: 0.117.0 (bot) - INFO - Instabot version: 0.117.0 Started
2021-06-27 18:40:30,882 - instabot version: 0.117.0 (bot) - DEBUG - Bot imported from /home/deep/anaconda3/envs/py36/lib/python3.6/site-packages/instabot/bot/bot.py
2021-06-27 18:40:30,885 - instabot version: 0.117.0 (api_login) - INFO - Not yet logged in starting: PRE-LOGIN FLOW!
2021-06-27 18:40:30,899 - instabot version: 0.117.0 (api) - WARNING - HTTPSConnectionPool(host='i.instagram.com', port=443): Max retries exceeded with url: /api/v1/accounts/get_prefill_candidates/ (Caused by NewConnectionError('<urllib3.connection.HTTPSConnection object at 0x7f53e52d04e0>: Failed to establish a new connection: [Errno -3] Temporary failure in name resolution',))
2021-06-27 18:40:30,905 - instabot version: 0.117.0 (api) - WARNING - HTTPSConnectionPool(host='i.instagram.com', port=443): Max retries exceeded with url: /api/v1/qe/sync/ (Caused by NewConnectionError('<urllib3.connection.HTTPSConnection object at 0x7f53e52d0240>: Failed to establish a new connection: [Errno -3] Temporary failure in name resolution',))
2021-06-27 18:40:30,911 - instabot version: 0.117.0 (api) - WARNING - HTTPSConnectionPool(host='i.instagram.com', port=443): Max retries exceeded with url: /api/v1/launcher/sync/ (Caused by NewConnectionError('<urllib3.connection.HTTPSConnection object at 0x7f53e52d0358>: Failed to establish a new connection: [Errno -3] Temporary failure in name resolution',))
2021-06-27 18:40:30,918 - instabot version: 0.117.0 (api) - WARNING - HTTPSConnectionPool(host='i.instagram.com', port=443): Max retries exceeded with url: /api/v1/accounts/contact_point_prefill/ (Caused by NewConnectionError('<urllib3.connection.HTTPSConnection object at 0x7f53e52d01d0>: Failed to establish a new connection: [Errno -3] Temporary failure in name resolution',))
